<robot name="aubo_i10">

<!-- base_link-->

  <link name="base_link">
    <inertial>
      <origin xyz="-2.7535E-06 0.00054789 0.02299" rpy="0 0 0" />
      <mass value="1.2345" />
      <inertia ixx="0.0029215" ixy="2.2046E-07" ixz="-3.4773E-08" iyy="0.0028546" iyz="-7.6362E-06" izz="0.0051176" />
    </inertial>
    <visual>
      <origin xyz="0 0 0" rpy="0 0 0" />
      <geometry>
        <mesh filename="package://aubo_description/meshes/aubo_i10/base_link.DAE" />
      </geometry>
      <material name="">
        <color rgba="1 1 1 1" />
      </material>
    </visual>
    <collision>
      <origin xyz="0 0 0" rpy="0 0 0" />
      <geometry>
        <mesh filename="package://aubo_description/meshes/aubo_i10/base_link.STL" />
      </geometry>
    </collision>
  </link>

<!-- shoulder_Link -->

  <link name="shoulder_Link">
    <inertial>
      <origin xyz="0.00029287 0.14173 0.54281" rpy="0 0 0" />
      <mass value="10.994" />
      <inertia ixx="2.2088" ixy="-0.00043922" ixz="-0.0025417" iyy="2.1473" iyz="-0.049088" izz="0.07998" />
    </inertial>
    <visual>
      <origin xyz="0 0 0" rpy="0 0 0" />
      <geometry>
        <mesh
          filename="package://aubo_description/meshes/aubo_i10/shoulder_Link.DAE" />
      </geometry>
      <material name="">
        <color rgba="0.89804 0.91765 0.92941 1" />
      </material>
    </visual>
    <collision>
      <origin xyz="0 0 0" rpy="0 0 0" />
      <geometry>
        <mesh filename="package://aubo_description/meshes/aubo_i10/shoulder_Link.STL" />
      </geometry>
    </collision>
  </link>

<!-- shoulder_joint -->

  <joint name="shoulder_joint" type="revolute">
    <origin xyz="0 0 0.1632" rpy="-8.7138E-17 -4.3534E-32 3.1416" />
    <parent link="base_link" />
    <child link="shoulder_Link" />
    <axis xyz="0 0 1" />
    <limit lower="-6.28" upper="6.28" effort="0" velocity="0" /> 
    <!-- <limit effort="0" lower="0.0" upper="3.05" velocity="0"/> -->
  </joint>

<!-- upperArm_Link -->

  <link name="upperArm_Link">
    <inertial>
      <origin xyz="0.31908 -3.7071E-06 -0.0042956" rpy="0 0 0" />
      <mass value="5.3139" />
      <inertia ixx="0.0095171" ixy="7.2849E-06" ixz="-6.7014E-06" iyy="0.11411" iyz="-1.1529E-06" izz="0.11411" />
    </inertial>
    <visual>
      <origin xyz="0 0 0" rpy="0 0 0" />
      <geometry>
        <mesh filename="package://aubo_description/meshes/aubo_i10/upperArm_Link.DAE" />
      </geometry>
      <material name="">
        <color rgba="0.89804 0.91765 0.92941 1" />
      </material>
    </visual>
    <collision>
      <origin xyz="0 0 0" rpy="0 0 0" />
      <geometry>
        <mesh filename="package://aubo_description/meshes/aubo_i10/upperArm_Link.STL" />
      </geometry>
    </collision>
  </link>

<!-- upperArm_Joint -->

  <joint name="upperArm_joint" type="revolute">
    <origin xyz="0 0.2013 0" rpy="-1.5708 2.8 0" />
    <parent link="shoulder_Link" />
    <child link="upperArm_Link" />
    <axis xyz="0 0 1" />
    <limit lower="-6.28" upper="6.28" effort="0" velocity="0" /> 
    <!-- <limit effort="0" lower="0.0" upper="1.80" velocity="0"/> -->      <!-- Previously 1.57 --> 
  </joint>

<!-- foreArm_Link -->

  <link name="foreArm_Link">
    <inertial>
      <origin xyz="0.24431 6.6794E-06 0.12549" rpy="0 0 0" />
      <mass value="3.1022" />
      <inertia ixx="0.0027288" ixy="-6.2713E-06" ixz="-0.0018082" iyy="0.097825" iyz="3.5731E-07" izz="0.097866" />
    </inertial>
    <visual>
      <origin xyz="0 0 0" rpy="0 0 0" />
      <geometry>
        <mesh filename="package://aubo_description/meshes/aubo_i10/foreArm_Link.DAE" />
      </geometry>
      <material name="">
        <color rgba="1 1 1 1" />
      </material>
    </visual>
    <collision>
      <origin xyz="0 0 0" rpy="0 0 0" />
      <geometry>
        <mesh filename="package://aubo_description/meshes/aubo_i10/foreArm_Link.STL" />
      </geometry>
    </collision>
  </link>

<!-- foreArm_Joint -->

  <joint name="foreArm_joint" type="revolute">
    <origin xyz="0.647 0 0" rpy="3.1416 -4.5954E-17 1.57" />
    <parent link="upperArm_Link" />
    <child link="foreArm_Link" />
    <axis xyz="0 0 1" />
    <limit lower="-3.10" upper="3.10" effort="0" velocity="0" /> 
    <!-- <limit effort="0" lower="-3.05" upper="1.58" velocity="0"/> -->
  </joint>

<!-- wrist1_Link -->

  <link name="wrist1_Link">
    <inertial>
      <origin xyz="5.2305E-07 0.00026581 -0.0027894" rpy="0 0 0" />
      <mass value="0.57981" />
      <inertia ixx="0.00088336" ixy="-6.425E-09" ixz="5.1594E-09" iyy="0.00046118" iyz="-1.0734E-06" izz="0.00085336" />
    </inertial>
    <visual>
      <origin xyz="0 0 0" rpy="0 0 0" />
      <geometry>
        <mesh filename="package://aubo_description/meshes/aubo_i10/wrist1_Link.DAE" />
      </geometry>
      <material name="">
        <color rgba="1 1 1 1" />
      </material>
    </visual>
    <collision>
      <origin xyz="0 0 0" rpy="0 0 0" />
      <geometry>
        <mesh filename="package://aubo_description/meshes/aubo_i10/wrist1_Link.STL" />
      </geometry>
    </collision>
  </link>

<!-- wrist1_Joint -->

  <joint name="wrist1_joint" type="revolute">
    <origin xyz="0.6005 0 0" rpy="-3.1416 -1.4294E-15 1.5708" />
    <parent link="foreArm_Link" />
    <child link="wrist1_Link" />
    <axis xyz="0 0 1" />
    <limit lower="-6.28" upper="6.28" effort="0" velocity="0" />
  </joint>

<!-- wrist2_Link -->

  <link name="wrist2_Link">
    <inertial>
      <origin xyz="-5.2305E-07 -0.00026581 -0.0027894" rpy="0 0 0" />
      <mass value="0.57981" />
      <inertia ixx="0.00088336" ixy="-6.4251E-09" ixz="-5.1594E-09" iyy="0.00046118" iyz="1.0734E-06" izz="0.00085336" />
    </inertial>
    <visual>
      <origin xyz="0 0 0" rpy="0 0 0" />
      <geometry>
        <mesh filename="package://aubo_description/meshes/aubo_i10/wrist2_Link.DAE" />
      </geometry>
      <material name="">
        <color rgba="1 1 1 1" />
      </material>
    </visual>
    <collision>
      <origin xyz="0 0 0" rpy="0 0 0" />
      <geometry>
        <mesh filename="package://aubo_description/meshes/aubo_i10/wrist2_Link.STL" />
      </geometry>
    </collision>
  </link>

<!-- wrist2_Joint -->

  <joint name="wrist2_joint" type="revolute">
    <origin xyz="0 0.1025 0" rpy="-1.5708 -7.0777E-16 -7.4101E-16" />
    <parent link="wrist1_Link" />
    <child link="wrist2_Link" />
    <axis xyz="0 0 1" />
    <limit lower="-6.28" upper="6.28" effort="0" velocity="0" />
  </joint>

<!-- wrist3_Link -->

  <link name="wrist3_Link">
    <inertial>
      <origin xyz="-2.2127E-09 0.00023722 -0.018629" rpy="0 0 0" />
      <mass value="0.13669" />
      <inertia ixx="6.0946E-05" ixy="9.3663E-12" ixz="-1.3841E-12" iyy="5.9501E-05" iyz="1.9944E-07" izz="9.6981E-05" />
    </inertial>
    <visual>
      <origin xyz="0 0 0" rpy="0 0 0" />
      <geometry>
        <mesh filename="package://aubo_description/meshes/aubo_i10/wrist3_Link.DAE" />
      </geometry>
      <material name="">
        <color rgba="1 1 1 1" />
      </material>
    </visual>
    <collision>
      <origin xyz="0 0 0" rpy="0 0 0" />
      <geometry>
        <mesh filename="package://aubo_description/meshes/aubo_i10/wrist3_Link.STL" />
      </geometry>
    </collision>
  </link>

<!-- wrist3_Joint -->

  <joint name="wrist3_joint" type="revolute">
    <origin xyz="0 -0.094 0" rpy="1.5708 0 6.7283E-16" />
    <parent link="wrist2_Link" />
    <child link="wrist3_Link" />
    <axis xyz="0 0 1" />
    <limit lower="-6.28" upper="6.28" effort="0" velocity="0" /> 
    <!-- <limit effort="0" lower="-1.57" upper="1.57" velocity="0"/> -->
  </joint>

    <link name="ee_link">
    <collision>
      <geometry>
        <box size="0.01 0.01 0.01"/>
      </geometry>
      <origin rpy="0 0 0" xyz="0 0 0"/>
    </collision>
     <visual>
    <origin xyz="0 0 0" rpy="0 0 0"/>
    <geometry>
      <box size="0.01 0.01 0.01"/>
    </geometry>
  </visual>
  </link>

  <joint name="ee_fixed_joint" type="fixed">
      <parent link="wrist3_Link" />
      <child link = "ee_link" />
      <origin xyz="0.0 0.0 0.0" rpy="0.0 0.0 1.57" />
    </joint>


<!-- Gripper V1.1 -->

  <link name="vacuum_gripper">
    <inertial> 
      <origin xyz="0 0 0" rpy="0 0 0"/> <mass value="0.8"/> <inertia ixx="0.1" ixy="0.0" ixz="0.0" iyy="0.1" iyz="0.0" izz="0.1"/>
    </inertial>
    <visual>
      <geometry>
        <!-- <mesh filename="package://aubo_description/meshes/gripper/vacuum/Gripper_V1_1_Body.stl" /> -->
        <mesh filename="package://aubo_description/meshes/gripper/vacuum/Gripper_V1_1_Body_300mm.stl" />
      </geometry>
      <material name="metal">
        <color rgba="0.5 0.5 0.6 1"/>
      </material>
    </visual>
    <collision>
      <geometry>
        <!-- <mesh filename="package://aubo_description/meshes/gripper/vacuum/Gripper_V1_1_Body_collision.dae" /> -->
        <mesh filename="package://aubo_description/meshes/gripper/vacuum/Gripper_V1_1_Body_300mm.stl" />
      </geometry>
       <material name="metal">
        <color rgba="0.5 0.5 0.6 1"/>
      </material>
    </collision>
  </link>

<!-- end of arm-vacuum gripper coupling link definitions --> 

  <!-- start of arm-gripper coupling joint definitions -->
  <joint name="wrist_to_gripper" type="fixed">
    <parent link="ee_link"/>
    <child link="vacuum_gripper"/>
    <origin xyz="0.0 0.0 0.0" rpy="0.0 1.57 0"/>
  </joint>

  <link name="vacuum_gripper_eef_link">
    <inertial> 
      <origin xyz="0 0 0" rpy="0 0 0"/> <mass value="0.1"/> <inertia ixx="0.1" ixy="0.0" ixz="0.0" iyy="0.1" iyz="0.0" izz="0.1"/>
    </inertial>
    <visual>
      <geometry>
        <mesh filename="package://aubo_description/meshes/gripper/vacuum/Gripper_V1_1_Cup.stl" />
      </geometry>
      <material name="metal">
        <color rgba="0.5 0.5 0.6 1"/>
      </material>
    </visual>
    <collision>
      <geometry>
        <mesh filename="package://aubo_description/meshes/gripper/vacuum/Gripper_V1_1_Cup_collision.dae" />
      </geometry>
       <material name="metal">
        <color rgba="0.5 0.5 0.6 1"/>
      </material>
    </collision>
  </link>

  <joint name="gripper_to_eef" type="fixed">
    <parent link="vacuum_gripper"/>
    <child link="vacuum_gripper_eef_link"/>
   <!-- <origin xyz="-0.55086 0.0 0.03418" rpy="0 0.0 0.0" />  -->
      <origin xyz="-0.25086 0.0 0.03418" rpy="0 0.0 0.0" /> 
      <axis xyz="0 0 1" />
      <limit lower="-1.8" upper="1.8" effort="28.0" velocity="12.14"/>
      <dynamics damping="0.0" friction="0.0"/>
  </joint>

  <link name="eef_to_suction" />

  <joint name="suction" type="fixed">
    <parent link="vacuum_gripper_eef_link"/>
    <child link="eef_to_suction"/>
    <origin xyz="-0.06 0.0 -0.03418" rpy="0.0 0.0 3.14159"/>
  </joint>

  <transmission name="gripper_eef_trans">
    <type>transmission_interface/SimpleTransmission</type>
    <joint name="gripper_to_eef">
      <hardwareInterface>PositionJointInterface</hardwareInterface>
    </joint>
    <actuator name="gripper_eef_motor">
      <mechanicalReduction>1</mechanicalReduction>
    </actuator>
  </transmission>

  <link name="world" />
  <joint name="world_joint" type="fixed">
    <parent link="world" />
    <child link = "base_link" />
    <origin xyz="0.0 0.0 1.2" rpy="0.0 3.14 0.0" />
  </joint>

</robot>
